Workbook

Sheet README
A1: Pharma Valuation Explorer: comparison and DCF model (version 0.1.0)
A3: What this is: public IFRS financials of Novartis (USD), GSK (GBP) and Novo Nordisk (DKK) for fiscal years 2023 to 2025, a comparison sheet, and a DCF of Novartis.
A4: Source of every number on the Data sheet: the companies' Form 20-F filings on SEC EDGAR (accession number and R page in each row). Millions of reporting currency, as filed.
A5: Fiscal years end 31 December for all three companies. Figures are as reported under IFRS. Company 'core' or 'adjusted' measures are not used.
A6: Novartis figures are continuing operations (the 2023 Sandoz spin-off is excluded). Revenue is net sales; other revenue and royalty income are excluded from revenue.
A7: Blue cells are inputs you can change. Everything else is a formula.
A8: The DCF defaults are the author's assumptions for exploring a range. They are not forecasts, guidance or investment advice.
A9: No share prices are included: no public price source with a clear reuse licence was available programmatically. The model gives a value per share you can compare with a price you choose.
A10: Risk-free rate: US Treasury 10-year yield on 2025-12-31 (FRED DGS10). Equity risk premium: Damodaran implied ERP, 2026-01-01.
A11: Not covered in the enterprise-to-equity bridge: litigation and tax provisions, off-balance-sheet commitments, pension surpluses, and operating-lease commitments outside IFRS 16 liabilities.
A12: See docs/methodology.md in the repository for definitions, the comparability rules and the validation results.

Sheet Data
A1: company | B1: fiscal_year | C1: field | D1: value | E1: currency | F1: accession | G1: source_page | H1: line_label | I1: note
A2: GSK | B2: 2023 | C2: buybacks | D2: 0 | E2: GBP | F2: 0001131399-26-000004 | G2: R7.htm | H2: Purchase of treasury shares
A3: GSK | B3: 2024 | C3: buybacks | D3: 0 | E3: GBP | F3: 0001131399-26-000004 | G3: R7.htm | H3: Purchase of treasury shares
A4: GSK | B4: 2025 | C4: buybacks | D4: 1377 | E4: GBP | F4: 0001131399-26-000004 | G4: R7.htm | H4: Purchase of treasury shares
A5: GSK | B5: 2023 | C5: capex_intangibles | D5: 1030 | E5: GBP | F5: 0001131399-26-000004 | G5: R7.htm | H5: Purchase of intangible assets
A6: GSK | B6: 2024 | C6: capex_intangibles | D6: 1583 | E6: GBP | F6: 0001131399-26-000004 | G6: R7.htm | H6: Purchase of intangible assets
A7: GSK | B7: 2025 | C7: capex_intangibles | D7: 1637 | E7: GBP | F7: 0001131399-26-000004 | G7: R7.htm | H7: Purchase of intangible assets
A8: GSK | B8: 2023 | C8: capex_ppe | D8: 1314 | E8: GBP | F8: 0001131399-26-000004 | G8: R7.htm | H8: Purchase of property, plant and equipment
A9: GSK | B9: 2024 | C9: capex_ppe | D9: 1399 | E9: GBP | F9: 0001131399-26-000004 | G9: R7.htm | H9: Purchase of property, plant and equipment
A10: GSK | B10: 2025 | C10: capex_ppe | D10: 1348 | E10: GBP | F10: 0001131399-26-000004 | G10: R7.htm | H10: Purchase of property, plant and equipment
A11: GSK | B11: 2023 | C11: cash | D11: 2936 | E11: GBP | F11: 0001131399-25-000007 | G11: R5.htm | H11: Cash and cash equivalents
A12: GSK | B12: 2024 | C12: cash | D12: 3870 | E12: GBP | F12: 0001131399-26-000004 | G12: R5.htm | H12: Cash and cash equivalents
A13: GSK | B13: 2025 | C13: cash | D13: 3397 | E13: GBP | F13: 0001131399-26-000004 | G13: R5.htm | H13: Cash and cash equivalents
... A22: GSK | B22: 2025 | C22: contingent_consideration_noncurrent | D22: 5385 | E22: GBP | F22: 0001131399-26-000004 | G22: R5.htm | H22: Contingent consideration liabilities
A23: GSK | B23: 2023 | C23: debt_current | D23: 2813 | E23: GBP | F23: 0001131399-25-000007 | G23: R5.htm | H23: Short-term borrowings | I23: Borrowings include lease liabilities
A24: GSK | B24: 2024 | C24: debt_current | D24: 2349 | E24: GBP | F24: 0001131399-26-000004 | G24: R5.htm | H24: Short-term borrowings | I24: Borrowings include lease liabilities
A25: GSK | B25: 2025 | C25: debt_current | D25: 3012 | E25: GBP | F25: 0001131399-26-000004 | G25: R5.htm | H25: Short-term borrowings | I25: Borrowings include lease liabilities
A26: GSK | B26: 2023 | C26: debt_noncurrent | D26: 15205 | E26: GBP | F26: 0001131399-25-000007 | G26: R5.htm | H26: Long-term borrowings | I26: Borrowings include lease liabilities
A27: GSK | B27: 2024 | C27: debt_noncurrent | D27: 14637 | E27: GBP | F27: 0001131399-26-000004 | G27: R5.htm | H27: Long-term borrowings | I27: Borrowings include lease liabilities
A28: GSK | B28: 2025 | C28: debt_noncurrent | D28: 14708 | E28: GBP | F28: 0001131399-26-000004 | G28: R5.htm | H28: Long-term borrowings | I28: Borrowings include lease liabilities
A29: GSK | B29: 2023 | C29: dividends_paid | D29: 2247 | E29: GBP | F29: 0001131399-26-000004 | G29: R7.htm | H29: Dividends paid to shareholders
A30: GSK | B30: 2024 | C30: dividends_paid | D30: 2444 | E30: GBP | F30: 0001131399-26-000004 | G30: R7.htm | H30: Dividends paid to shareholders
A31: GSK | B31: 2025 | C31: dividends_paid | D31: 2564 | E31: GBP | F31: 0001131399-26-000004 | G31: R7.htm | H31: Dividends paid to shareholders
A32: GSK | B32: 2023 | C32: equity_method_investments | D32: 55 | E32: GBP | F32: 0001131399-25-000007 | G32: R5.htm | H32: Investments in associates and joint ventures
A33: GSK | B33: 2024 | C33: equity_method_investments | D33: 96 | E33: GBP | F33: 0001131399-26-000004 | G33: R5.htm | H33: Investments in associates and joint ventures
A34: GSK | B34: 2025 | C34: equity_method_investments | D34: 89 | E34: GBP | F34: 0001131399-26-000004 | G34: R5.htm | H34: Investments in associates and joint ventures
A35: GSK | B35: 2023 | C35: income_tax | D35: 756 | E35: GBP | F35: 0001131399-26-000004 | G35: R3.htm | H35: Taxation
A36: GSK | B36: 2024 | C36: income_tax | D36: 526 | E36: GBP | F36: 0001131399-26-000004 | G36: R3.htm | H36: Taxation
A37: GSK | B37: 2025 | C37: income_tax | D37: 1112 | E37: GBP | F37: 0001131399-26-000004 | G37: R3.htm | H37: Taxation
A38: GSK | B38: 2023 | C38: interest_paid_outside_cfo | D38: 766 | E38: GBP | F38: 0001131399-26-000004 | G38: R7.htm | H38: Interest paid | I38: GSK reports interest paid in financing activities
A39: GSK | B39: 2024 | C39: interest_paid_outside_cfo | D39: 632 | E39: GBP | F39: 0001131399-26-000004 | G39: R7.htm | H39: Interest paid | I39: GSK reports interest paid in financing activities
A40: GSK | B40: 2025 | C40: interest_paid_outside_cfo | D40: 679 | E40: GBP | F40: 0001131399-26-000004 | G40: R7.htm | H40: Interest paid | I40: GSK reports interest paid in financing activities
A41: GSK | B41: 2023 | C41: interest_received_outside_cfo | D41: 115 | E41: GBP | F41: 0001131399-26-000004 | G41: R7.htm | H41: Interest received | I41: GSK reports interest received in investing activities
A42: GSK | B42: 2024 | C42: interest_received_outside_cfo | D42: 138 | E42: GBP | F42: 0001131399-26-000004 | G42: R7.htm | H42: Interest received | I42: GSK reports interest received in investing activities
A43: GSK | B43: 2025 | C43: interest_received_outside_cfo | D43: 154 | E43: GBP | F43: 0001131399-26-000004 | G43: R7.htm | H43: Interest received | I43: GSK reports interest received in investing activities
A44: GSK | B44: 2023 | C44: inventories | D44: 5498 | E44: GBP | F44: 0001131399-25-000007 | G44: R5.htm | H44: Inventories
A45: GSK | B45: 2024 | C45: inventories | D45: 5669 | E45: GBP | F45: 0001131399-26-000004 | G45: R5.htm | H45: Inventories
A46: GSK | B46: 2025 | C46: inventories | D46: 5924 | E46: GBP | F46: 0001131399-26-000004 | G46: R5.htm | H46: Inventories
A47: GSK | B47: 2023 | C47: lease_principal | D47: 197 | E47: GBP | F47: 0001131399-26-000004 | G47: R7.htm | H47: Repayment of lease liabilities
A48: GSK | B48: 2024 | C48: lease_principal | D48: 226 | E48: GBP | F48: 0001131399-26-000004 | G48: R7.htm | H48: Repayment of lease liabilities
...

Sheet Comparison
A1: Comparable metrics, as reported (millions of reporting currency)
B2: USD | C2: USD | D2: USD | E2: GBP | F2: GBP | G2: GBP | H2: DKK | I2: DKK | J2: DKK
A3: Metric | B3: Novartis 2023 | C3: Novartis 2024 | D3: Novartis 2025 | E3: GSK 2023 | F3: GSK 2024 | G3: GSK 2025 | H3: Novo Nordisk 2023 | I3: Novo Nordisk 2024 | J3: Novo Nordisk 2025
A4: Revenue (net sales) | B4: =SUMIFS(Data!$D$2:$D$277,Data!$A$2:$A$277,"Novartis",Data!$B$2:$B$277,2023,Data!$C$2:$C$277,"revenue") | C4: =SUMIFS(Data!$D$2:$D$277,Data!$A$2:$A$277,"Novartis",Data!$B$2:$B$277,2024,Data!$C$2:$C$277,"revenue") | D4: =SUMIFS(Data!$D$2:$D$277,Data!$A$2:$A$277,"Novartis",Data!$B$2:$B$277,2025,Data!$C$2:$C$277,"revenue") | E4: =SUMIFS(Data!$D$2:$D$277,Data!$A$2:$A$277,"GSK",Data!$B$2:$B$277,2023,Data!$C$2:$C$277,"revenue") | F4: =SUMIFS(Data!$D$2:$D$277,Data!$A$2:$A$277,"GSK",Data!$B$2:$B$277,2024,Data!$C$2:$C$277,"revenue") | G4: =SUMIFS(Data!$D$2:$D$277,Data!$A$2:$A$277,"GSK",Data!$B$2:$B$277,2025,Data!$C$2:$C$277,"revenue") | H4: =SUMIFS(Data!$D$2:$D$277,Data!$A$2:$A$277,"Novo Nordisk",Data!$B$2:$B$277,2023,Data!$C$2:$C$277,"revenue") | I4: =SUMIFS(Data!$D$2:$D$277,Data!$A$2:$A$277,"Novo Nordisk",Data!$B$2:$B$277,2024,Data!$C$2:$C$277,"revenue") | J4: =SUMIFS(Data!$D$2:$D$277,Data!$A$2:$A$277,"Novo Nordisk",Data!$B$2:$B$277,2025,Data!$C$2:$C$277,"revenue")
A5: Operating income (reported) | B5: =SUMIFS(Data!$D$2:$D$277,Data!$A$2:$A$277,"Novartis",Data!$B$2:$B$277,2023,Data!$C$2:$C$277,"operating_income") | C5: =SUMIFS(Data!$D$2:$D$277,Data!$A$2:$A$277,"Novartis",Data!$B$2:$B$277,2024,Data!$C$2:$C$277,"operating_income") | D5: =SUMIFS(Data!$D$2:$D$277,Data!$A$2:$A$277,"Novartis",Data!$B$2:$B$277,2025,Data!$C$2:$C$277,"operating_income") | E5: =SUMIFS(Data!$D$2:$D$277,Data!$A$2:$A$277,"GSK",Data!$B$2:$B$277,2023,Data!$C$2:$C$277,"operating_income") | F5: =SUMIFS(Data!$D$2:$D$277,Data!$A$2:$A$277,"GSK",Data!$B$2:$B$277,2024,Data!$C$2:$C$277,"operating_income") | G5: =SUMIFS(Data!$D$2:$D$277,Data!$A$2:$A$277,"GSK",Data!$B$2:$B$277,2025,Data!$C$2:$C$277,"operating_income") | H5: =SUMIFS(Data!$D$2:$D$277,Data!$A$2:$A$277,"Novo Nordisk",Data!$B$2:$B$277,2023,Data!$C$2:$C$277,"operating_income") | I5: =SUMIFS(Data!$D$2:$D$277,Data!$A$2:$A$277,"Novo Nordisk",Data!$B$2:$B$277,2024,Data!$C$2:$C$277,"operating_income") | J5: =SUMIFS(Data!$D$2:$D$277,Data!$A$2:$A$277,"Novo Nordisk",Data!$B$2:$B$277,2025,Data!$C$2:$C$277,"operating_income")
A6: Research and development expense | B6: =SUMIFS(Data!$D$2:$D$277,Data!$A$2:$A$277,"Novartis",Data!$B$2:$B$277,2023,Data!$C$2:$C$277,"r_and_d") | C6: =SUMIFS(Data!$D$2:$D$277,Data!$A$2:$A$277,"Novartis",Data!$B$2:$B$277,2024,Data!$C$2:$C$277,"r_and_d") | D6: =SUMIFS(Data!$D$2:$D$277,Data!$A$2:$A$277,"Novartis",Data!$B$2:$B$277,2025,Data!$C$2:$C$277,"r_and_d") | E6: =SUMIFS(Data!$D$2:$D$277,Data!$A$2:$A$277,"GSK",Data!$B$2:$B$277,2023,Data!$C$2:$C$277,"r_and_d") | F6: =SUMIFS(Data!$D$2:$D$277,Data!$A$2:$A$277,"GSK",Data!$B$2:$B$277,2024,Data!$C$2:$C$277,"r_and_d") | G6: =SUMIFS(Data!$D$2:$D$277,Data!$A$2:$A$277,"GSK",Data!$B$2:$B$277,2025,Data!$C$2:$C$277,"r_and_d") | H6: =SUMIFS(Data!$D$2:$D$277,Data!$A$2:$A$277,"Novo Nordisk",Data!$B$2:$B$277,2023,Data!$C$2:$C$277,"r_and_d") | I6: =SUMIFS(Data!$D$2:$D$277,Data!$A$2:$A$277,"Novo Nordisk",Data!$B$2:$B$277,2024,Data!$C$2:$C$277,"r_and_d") | J6: =SUMIFS(Data!$D$2:$D$277,Data!$A$2:$A$277,"Novo Nordisk",Data!$B$2:$B$277,2025,Data!$C$2:$C$277,"r_and_d")
A7: Income tax expense | B7: =SUMIFS(Data!$D$2:$D$277,Data!$A$2:$A$277,"Novartis",Data!$B$2:$B$277,2023,Data!$C$2:$C$277,"income_tax") | C7: =SUMIFS(Data!$D$2:$D$277,Data!$A$2:$A$277,"Novartis",Data!$B$2:$B$277,2024,Data!$C$2:$C$277,"income_tax") | D7: =SUMIFS(Data!$D$2:$D$277,Data!$A$2:$A$277,"Novartis",Data!$B$2:$B$277,2025,Data!$C$2:$C$277,"income_tax") | E7: =SUMIFS(Data!$D$2:$D$277,Data!$A$2:$A$277,"GSK",Data!$B$2:$B$277,2023,Data!$C$2:$C$277,"income_tax") | F7: =SUMIFS(Data!$D$2:$D$277,Data!$A$2:$A$277,"GSK",Data!$B$2:$B$277,2024,Data!$C$2:$C$277,"income_tax") | G7: =SUMIFS(Data!$D$2:$D$277,Data!$A$2:$A$277,"GSK",Data!$B$2:$B$277,2025,Data!$C$2:$C$277,"income_tax") | H7: =SUMIFS(Data!$D$2:$D$277,Data!$A$2:$A$277,"Novo Nordisk",Data!$B$2:$B$277,2023,Data!$C$2:$C$277,"income_tax") | I7: =SUMIFS(Data!$D$2:$D$277,Data!$A$2:$A$277,"Novo Nordisk",Data!$B$2:$B$277,2024,Data!$C$2:$C$277,"income_tax") | J7: =SUMIFS(Data!$D$2:$D$277,Data!$A$2:$A$277,"Novo Nordisk",Data!$B$2:$B$277,2025,Data!$C$2:$C$277,"income_tax")
A8: Income before tax | B8: =SUMIFS(Data!$D$2:$D$277,Data!$A$2:$A$277,"Novartis",Data!$B$2:$B$277,2023,Data!$C$2:$C$277,"pretax_income") | C8: =SUMIFS(Data!$D$2:$D$277,Data!$A$2:$A$277,"Novartis",Data!$B$2:$B$277,2024,Data!$C$2:$C$277,"pretax_income") | D8: =SUMIFS(Data!$D$2:$D$277,Data!$A$2:$A$277,"Novartis",Data!$B$2:$B$277,2025,Data!$C$2:$C$277,"pretax_income") | E8: =SUMIFS(Data!$D$2:$D$277,Data!$A$2:$A$277,"GSK",Data!$B$2:$B$277,2023,Data!$C$2:$C$277,"pretax_income") | F8: =SUMIFS(Data!$D$2:$D$277,Data!$A$2:$A$277,"GSK",Data!$B$2:$B$277,2024,Data!$C$2:$C$277,"pretax_income") | G8: =SUMIFS(Data!$D$2:$D$277,Data!$A$2:$A$277,"GSK",Data!$B$2:$B$277,2025,Data!$C$2:$C$277,"pretax_income") | H8: =SUMIFS(Data!$D$2:$D$277,Data!$A$2:$A$277,"Novo Nordisk",Data!$B$2:$B$277,2023,Data!$C$2:$C$277,"pretax_income") | I8: =SUMIFS(Data!$D$2:$D$277,Data!$A$2:$A$277,"Novo Nordisk",Data!$B$2:$B$277,2024,Data!$C$2:$C$277,"pretax_income") | J8: =SUMIFS(Data!$D$2:$D$277,Data!$A$2:$A$277,"Novo Nordisk",Data!$B$2:$B$277,2025,Data!$C$2:$C$277,"pretax_income")
A9: Net income (continuing operations) | B9: =SUMIFS(Data!$D$2:$D$277,Data!$A$2:$A$277,"Novartis",Data!$B$2:$B$277,2023,Data!$C$2:$C$277,"net_income") | C9: =SUMIFS(Data!$D$2:$D$277,Data!$A$2:$A$277,"Novartis",Data!$B$2:$B$277,2024,Data!$C$2:$C$277,"net_income") | D9: =SUMIFS(Data!$D$2:$D$277,Data!$A$2:$A$277,"Novartis",Data!$B$2:$B$277,2025,Data!$C$2:$C$277,"net_income") | E9: =SUMIFS(Data!$D$2:$D$277,Data!$A$2:$A$277,"GSK",Data!$B$2:$B$277,2023,Data!$C$2:$C$277,"net_income") | F9: =SUMIFS(Data!$D$2:$D$277,Data!$A$2:$A$277,"GSK",Data!$B$2:$B$277,2024,Data!$C$2:$C$277,"net_income") | G9: =SUMIFS(Data!$D$2:$D$277,Data!$A$2:$A$277,"GSK",Data!$B$2:$B$277,2025,Data!$C$2:$C$277,"net_income") | H9: =SUMIFS(Data!$D$2:$D$277,Data!$A$2:$A$277,"Novo Nordisk",Data!$B$2:$B$277,2023,Data!$C$2:$C$277,"net_income") | I9: =SUMIFS(Data!$D$2:$D$277,Data!$A$2:$A$277,"Novo Nordisk",Data!$B$2:$B$277,2024,Data!$C$2:$C$277,"net_income") | J9: =SUMIFS(Data!$D$2:$D$277,Data!$A$2:$A$277,"Novo Nordisk",Data!$B$2:$B$277,2025,Data!$C$2:$C$277,"net_income")
A10: Operating cash flow | B10: =SUMIFS(Data!$D$2:$D$277,Data!$A$2:$A$277,"Novartis",Data!$B$2:$B$277,2023,Data!$C$2:$C$277,"cfo") | C10: =SUMIFS(Data!$D$2:$D$277,Data!$A$2:$A$277,"Novartis",Data!$B$2:$B$277,2024,Data!$C$2:$C$277,"cfo") | D10: =SUMIFS(Data!$D$2:$D$277,Data!$A$2:$A$277,"Novartis",Data!$B$2:$B$277,2025,Data!$C$2:$C$277,"cfo") | E10: =SUMIFS(Data!$D$2:$D$277,Data!$A$2:$A$277,"GSK",Data!$B$2:$B$277,2023,Data!$C$2:$C$277,"cfo") | F10: =SUMIFS(Data!$D$2:$D$277,Data!$A$2:$A$277,"GSK",Data!$B$2:$B$277,2024,Data!$C$2:$C$277,"cfo") | G10: =SUMIFS(Data!$D$2:$D$277,Data!$A$2:$A$277,"GSK",Data!$B$2:$B$277,2025,Data!$C$2:$C$277,"cfo") | H10: =SUMIFS(Data!$D$2:$D$277,Data!$A$2:$A$277,"Novo Nordisk",Data!$B$2:$B$277,2023,Data!$C$2:$C$277,"cfo") | I10: =SUMIFS(Data!$D$2:$D$277,Data!$A$2:$A$277,"Novo Nordisk",Data!$B$2:$B$277,2024,Data!$C$2:$C$277,"cfo") | J10: =SUMIFS(Data!$D$2:$D$277,Data!$A$2:$A$277,"Novo Nordisk",Data!$B$2:$B$277,2025,Data!$C$2:$C$277,"cfo")
A11: Capex: property, plant and equipment | B11: =SUMIFS(Data!$D$2:$D$277,Data!$A$2:$A$277,"Novartis",Data!$B$2:$B$277,2023,Data!$C$2:$C$277,"capex_ppe") | C11: =SUMIFS(Data!$D$2:$D$277,Data!$A$2:$A$277,"Novartis",Data!$B$2:$B$277,2024,Data!$C$2:$C$277,"capex_ppe") | D11: =SUMIFS(Data!$D$2:$D$277,Data!$A$2:$A$277,"Novartis",Data!$B$2:$B$277,2025,Data!$C$2:$C$277,"capex_ppe") | E11: =SUMIFS(Data!$D$2:$D$277,Data!$A$2:$A$277,"GSK",Data!$B$2:$B$277,2023,Data!$C$2:$C$277,"capex_ppe") | F11: =SUMIFS(Data!$D$2:$D$277,Data!$A$2:$A$277,"GSK",Data!$B$2:$B$277,2024,Data!$C$2:$C$277,"capex_ppe") | G11: =SUMIFS(Data!$D$2:$D$277,Data!$A$2:$A$277,"GSK",Data!$B$2:$B$277,2025,Data!$C$2:$C$277,"capex_ppe") | H11: =SUMIFS(Data!$D$2:$D$277,Data!$A$2:$A$277,"Novo Nordisk",Data!$B$2:$B$277,2023,Data!$C$2:$C$277,"capex_ppe") | I11: =SUMIFS(Data!$D$2:$D$277,Data!$A$2:$A$277,"Novo Nordisk",Data!$B$2:$B$277,2024,Data!$C$2:$C$277,"capex_ppe") | J11: =SUMIFS(Data!$D$2:$D$277,Data!$A$2:$A$277,"Novo Nordisk",Data!$B$2:$B$277,2025,Data!$C$2:$C$277,"capex_ppe")
A12: Capex: intangible assets | B12: =SUMIFS(Data!$D$2:$D$277,Data!$A$2:$A$277,"Novartis",Data!$B$2:$B$277,2023,Data!$C$2:$C$277,"capex_intangibles") | C12: =SUMIFS(Data!$D$2:$D$277,Data!$A$2:$A$277,"Novartis",Data!$B$2:$B$277,2024,Data!$C$2:$C$277,"capex_intangibles") | D12: =SUMIFS(Data!$D$2:$D$277,Data!$A$2:$A$277,"Novartis",Data!$B$2:$B$277,2025,Data!$C$2:$C$277,"capex_intangibles") | E12: =SUMIFS(Data!$D$2:$D$277,Data!$A$2:$A$277,"GSK",Data!$B$2:$B$277,2023,Data!$C$2:$C$277,"capex_intangibles") | F12: =SUMIFS(Data!$D$2:$D$277,Data!$A$2:$A$277,"GSK",Data!$B$2:$B$277,2024,Data!$C$2:$C$277,"capex_intangibles") | G12: =SUMIFS(Data!$D$2:$D$277,Data!$A$2:$A$277,"GSK",Data!$B$2:$B$277,2025,Data!$C$2:$C$277,"capex_intangibles") | H12: =SUMIFS(Data!$D$2:$D$277,Data!$A$2:$A$277,"Novo Nordisk",Data!$B$2:$B$277,2023,Data!$C$2:$C$277,"capex_intangibles") | I12: =SUMIFS(Data!$D$2:$D$277,Data!$A$2:$A$277,"Novo Nordisk",Data!$B$2:$B$277,2024,Data!$C$2:$C$277,"capex_intangibles") | J12: =SUMIFS(Data!$D$2:$D$277,Data!$A$2:$A$277,"Novo Nordisk",Data!$B$2:$B$277,2025,Data!$C$2:$C$277,"capex_intangibles")
A13: Interest paid, if reported outside operating cash flow | B13: =SUMIFS(Data!$D$2:$D$277,Data!$A$2:$A$277,"Novartis",Data!$B$2:$B$277,2023,Data!$C$2:$C$277,"interest_paid_outside_cfo") | C13: =SUMIFS(Data!$D$2:$D$277,Data!$A$2:$A$277,"Novartis",Data!$B$2:$B$277,2024,Data!$C$2:$C$277,"interest_paid_outside_cfo") | D13: =SUMIFS(Data!$D$2:$D$277,Data!$A$2:$A$277,"Novartis",Data!$B$2:$B$277,2025,Data!$C$2:$C$277,"interest_paid_outside_cfo") | E13: =SUMIFS(Data!$D$2:$D$277,Data!$A$2:$A$277,"GSK",Data!$B$2:$B$277,2023,Data!$C$2:$C$277,"interest_paid_outside_cfo") | F13: =SUMIFS(Data!$D$2:$D$277,Data!$A$2:$A$277,"GSK",Data!$B$2:$B$277,2024,Data!$C$2:$C$277,"interest_paid_outside_cfo") | G13: =SUMIFS(Data!$D$2:$D$277,Data!$A$2:$A$277,"GSK",Data!$B$2:$B$277,2025,Data!$C$2:$C$277,"interest_paid_outside_cfo") | H13: =SUMIFS(Data!$D$2:$D$277,Data!$A$2:$A$277,"Novo Nordisk",Data!$B$2:$B$277,2023,Data!$C$2:$C$277,"interest_paid_outside_cfo") | I13: =SUMIFS(Data!$D$2:$D$277,Data!$A$2:$A$277,"Novo Nordisk",Data!$B$2:$B$277,2024,Data!$C$2:$C$277,"interest_paid_outside_cfo") | J13: =SUMIFS(Data!$D$2:$D$277,Data!$A$2:$A$277,"Novo Nordisk",Data!$B$2:$B$277,2025,Data!$C$2:$C$277,"interest_paid_outside_cfo")
A14: Interest received, if reported outside operating cash flow | B14: =SUMIFS(Data!$D$2:$D$277,Data!$A$2:$A$277,"Novartis",Data!$B$2:$B$277,2023,Data!$C$2:$C$277,"interest_received_outside_cfo") | C14: =SUMIFS(Data!$D$2:$D$277,Data!$A$2:$A$277,"Novartis",Data!$B$2:$B$277,2024,Data!$C$2:$C$277,"interest_received_outside_cfo") | D14: =SUMIFS(Data!$D$2:$D$277,Data!$A$2:$A$277,"Novartis",Data!$B$2:$B$277,2025,Data!$C$2:$C$277,"interest_received_outside_cfo") | E14: =SUMIFS(Data!$D$2:$D$277,Data!$A$2:$A$277,"GSK",Data!$B$2:$B$277,2023,Data!$C$2:$C$277,"interest_received_outside_cfo") | F14: =SUMIFS(Data!$D$2:$D$277,Data!$A$2:$A$277,"GSK",Data!$B$2:$B$277,2024,Data!$C$2:$C$277,"interest_received_outside_cfo") | G14: =SUMIFS(Data!$D$2:$D$277,Data!$A$2:$A$277,"GSK",Data!$B$2:$B$277,2025,Data!$C$2:$C$277,"interest_received_outside_cfo") | H14: =SUMIFS(Data!$D$2:$D$277,Data!$A$2:$A$277,"Novo Nordisk",Data!$B$2:$B$277,2023,Data!$C$2:$C$277,"interest_received_outside_cfo") | I14: =SUMIFS(Data!$D$2:$D$277,Data!$A$2:$A$277,"Novo Nordisk",Data!$B$2:$B$277,2024,Data!$C$2:$C$277,"interest_received_outside_cfo") | J14: =SUMIFS(Data!$D$2:$D$277,Data!$A$2:$A$277,"Novo Nordisk",Data!$B$2:$B$277,2025,Data!$C$2:$C$277,"interest_received_outside_cfo")
A15: Borrowings: current | B15: =SUMIFS(Data!$D$2:$D$277,Data!$A$2:$A$277,"Novartis",Data!$B$2:$B$277,2023,Data!$C$2:$C$277,"debt_current") | C15: =SUMIFS(Data!$D$2:$D$277,Data!$A$2:$A$277,"Novartis",Data!$B$2:$B$277,2024,Data!$C$2:$C$277,"debt_current") | D15: =SUMIFS(Data!$D$2:$D$277,Data!$A$2:$A$277,"Novartis",Data!$B$2:$B$277,2025,Data!$C$2:$C$277,"debt_current") | E15: =SUMIFS(Data!$D$2:$D$277,Data!$A$2:$A$277,"GSK",Data!$B$2:$B$277,2023,Data!$C$2:$C$277,"debt_current") | F15: =SUMIFS(Data!$D$2:$D$277,Data!$A$2:$A$277,"GSK",Data!$B$2:$B$277,2024,Data!$C$2:$C$277,"debt_current") | G15: =SUMIFS(Data!$D$2:$D$277,Data!$A$2:$A$277,"GSK",Data!$B$2:$B$277,2025,Data!$C$2:$C$277,"debt_current") | H15: =SUMIFS(Data!$D$2:$D$277,Data!$A$2:$A$277,"Novo Nordisk",Data!$B$2:$B$277,2023,Data!$C$2:$C$277,"debt_current") | I15: =SUMIFS(Data!$D$2:$D$277,Data!$A$2:$A$277,"Novo Nordisk",Data!$B$2:$B$277,2024,Data!$C$2:$C$277,"debt_current") | J15: =SUMIFS(Data!$D$2:$D$277,Data!$A$2:$A$277,"Novo Nordisk",Data!$B$2:$B$277,2025,Data!$C$2:$C$277,"debt_current")
A16: Borrowings: non-current | B16: =SUMIFS(Data!$D$2:$D$277,Data!$A$2:$A$277,"Novartis",Data!$B$2:$B$277,2023,Data!$C$2:$C$277,"debt_noncurrent") | C16: =SUMIFS(Data!$D$2:$D$277,Data!$A$2:$A$277,"Novartis",Data!$B$2:$B$277,2024,Data!$C$2:$C$277,"debt_noncurrent") | D16: =SUMIFS(Data!$D$2:$D$277,Data!$A$2:$A$277,"Novartis",Data!$B$2:$B$277,2025,Data!$C$2:$C$277,"debt_noncurrent") | E16: =SUMIFS(Data!$D$2:$D$277,Data!$A$2:$A$277,"GSK",Data!$B$2:$B$277,2023,Data!$C$2:$C$277,"debt_noncurrent") | F16: =SUMIFS(Data!$D$2:$D$277,Data!$A$2:$A$277,"GSK",Data!$B$2:$B$277,2024,Data!$C$2:$C$277,"debt_noncurrent") | G16: =SUMIFS(Data!$D$2:$D$277,Data!$A$2:$A$277,"GSK",Data!$B$2:$B$277,2025,Data!$C$2:$C$277,"debt_noncurrent") | H16: =SUMIFS(Data!$D$2:$D$277,Data!$A$2:$A$277,"Novo Nordisk",Data!$B$2:$B$277,2023,Data!$C$2:$C$277,"debt_noncurrent") | I16: =SUMIFS(Data!$D$2:$D$277,Data!$A$2:$A$277,"Novo Nordisk",Data!$B$2:$B$277,2024,Data!$C$2:$C$277,"debt_noncurrent") | J16: =SUMIFS(Data!$D$2:$D$277,Data!$A$2:$A$277,"Novo Nordisk",Data!$B$2:$B$277,2025,Data!$C$2:$C$277,"debt_noncurrent")
A17: Lease liabilities: current (if separate) | B17: =SUMIFS(Data!$D$2:$D$277,Data!$A$2:$A$277,"Novartis",Data!$B$2:$B$277,2023,Data!$C$2:$C$277,"lease_current") | C17: =SUMIFS(Data!$D$2:$D$277,Data!$A$2:$A$277,"Novartis",Data!$B$2:$B$277,2024,Data!$C$2:$C$277,"lease_current") | D17: =SUMIFS(Data!$D$2:$D$277,Data!$A$2:$A$277,"Novartis",Data!$B$2:$B$277,2025,Data!$C$2:$C$277,"lease_current") | E17: =SUMIFS(Data!$D$2:$D$277,Data!$A$2:$A$277,"GSK",Data!$B$2:$B$277,2023,Data!$C$2:$C$277,"lease_current") | F17: =SUMIFS(Data!$D$2:$D$277,Data!$A$2:$A$277,"GSK",Data!$B$2:$B$277,2024,Data!$C$2:$C$277,"lease_current") | G17: =SUMIFS(Data!$D$2:$D$277,Data!$A$2:$A$277,"GSK",Data!$B$2:$B$277,2025,Data!$C$2:$C$277,"lease_current") | H17: =SUMIFS(Data!$D$2:$D$277,Data!$A$2:$A$277,"Novo Nordisk",Data!$B$2:$B$277,2023,Data!$C$2:$C$277,"lease_current") | I17: =SUMIFS(Data!$D$2:$D$277,Data!$A$2:$A$277,"Novo Nordisk",Data!$B$2:$B$277,2024,Data!$C$2:$C$277,"lease_current") | J17: =SUMIFS(Data!$D$2:$D$277,Data!$A$2:$A$277,"Novo Nordisk",Data!$B$2:$B$277,2025,Data!$C$2:$C$277,"lease_current")
A18: Lease liabilities: non-current (if separate) | B18: =SUMIFS(Data!$D$2:$D$277,Data!$A$2:$A$277,"Novartis",Data!$B$2:$B$277,2023,Data!$C$2:$C$277,"lease_noncurrent") | C18: =SUMIFS(Data!$D$2:$D$277,Data!$A$2:$A$277,"Novartis",Data!$B$2:$B$277,2024,Data!$C$2:$C$277,"lease_noncurrent") | D18: =SUMIFS(Data!$D$2:$D$277,Data!$A$2:$A$277,"Novartis",Data!$B$2:$B$277,2025,Data!$C$2:$C$277,"lease_noncurrent") | E18: =SUMIFS(Data!$D$2:$D$277,Data!$A$2:$A$277,"GSK",Data!$B$2:$B$277,2023,Data!$C$2:$C$277,"lease_noncurrent") | F18: =SUMIFS(Data!$D$2:$D$277,Data!$A$2:$A$277,"GSK",Data!$B$2:$B$277,2024,Data!$C$2:$C$277,"lease_noncurrent") | G18: =SUMIFS(Data!$D$2:$D$277,Data!$A$2:$A$277,"GSK",Data!$B$2:$B$277,2025,Data!$C$2:$C$277,"lease_noncurrent") | H18: =SUMIFS(Data!$D$2:$D$277,Data!$A$2:$A$277,"Novo Nordisk",Data!$B$2:$B$277,2023,Data!$C$2:$C$277,"lease_noncurrent") | I18: =SUMIFS(Data!$D$2:$D$277,Data!$A$2:$A$277,"Novo Nordisk",Data!$B$2:$B$277,2024,Data!$C$2:$C$277,"lease_noncurrent") | J18: =SUMIFS(Data!$D$2:$D$277,Data!$A$2:$A$277,"Novo Nordisk",Data!$B$2:$B$277,2025,Data!$C$2:$C$277,"lease_noncurrent")
A19: Contingent consideration: current (debt-like) | B19: =SUMIFS(Data!$D$2:$D$277,Data!$A$2:$A$277,"Novartis",Data!$B$2:$B$277,2023,Data!$C$2:$C$277,"contingent_consideration_current") | C19: =SUMIFS(Data!$D$2:$D$277,Data!$A$2:$A$277,"Novartis",Data!$B$2:$B$277,2024,Data!$C$2:$C$277,"contingent_consideration_current") | D19: =SUMIFS(Data!$D$2:$D$277,Data!$A$2:$A$277,"Novartis",Data!$B$2:$B$277,2025,Data!$C$2:$C$277,"contingent_consideration_current") | E19: =SUMIFS(Data!$D$2:$D$277,Data!$A$2:$A$277,"GSK",Data!$B$2:$B$277,2023,Data!$C$2:$C$277,"contingent_consideration_current") | F19: =SUMIFS(Data!$D$2:$D$277,Data!$A$2:$A$277,"GSK",Data!$B$2:$B$277,2024,Data!$C$2:$C$277,"contingent_consideration_current") | G19: =SUMIFS(Data!$D$2:$D$277,Data!$A$2:$A$277,"GSK",Data!$B$2:$B$277,2025,Data!$C$2:$C$277,"contingent_consideration_current") | H19: =SUMIFS(Data!$D$2:$D$277,Data!$A$2:$A$277,"Novo Nordisk",Data!$B$2:$B$277,2023,Data!$C$2:$C$277,"contingent_consideration_current") | I19: =SUMIFS(Data!$D$2:$D$277,Data!$A$2:$A$277,"Novo Nordisk",Data!$B$2:$B$277,2024,Data!$C$2:$C$277,"contingent_consideration_current") | J19: =SUMIFS(Data!$D$2:$D$277,Data!$A$2:$A$277,"Novo Nordisk",Data!$B$2:$B$277,2025,Data!$C$2:$C$277,"contingent_consideration_current")
A20: Contingent consideration: non-current (debt-like) | B20: =SUMIFS(Data!$D$2:$D$277,Data!$A$2:$A$277,"Novartis",Data!$B$2:$B$277,2023,Data!$C$2:$C$277,"contingent_consideration_noncurrent") | C20: =SUMIFS(Data!$D$2:$D$277,Data!$A$2:$A$277,"Novartis",Data!$B$2:$B$277,2024,Data!$C$2:$C$277,"contingent_consideration_noncurrent") | D20: =SUMIFS(Data!$D$2:$D$277,Data!$A$2:$A$277,"Novartis",Data!$B$2:$B$277,2025,Data!$C$2:$C$277,"contingent_consideration_noncurrent") | E20: =SUMIFS(Data!$D$2:$D$277,Data!$A$2:$A$277,"GSK",Data!$B$2:$B$277,2023,Data!$C$2:$C$277,"contingent_consideration_noncurrent") | F20: =SUMIFS(Data!$D$2:$D$277,Data!$A$2:$A$277,"GSK",Data!$B$2:$B$277,2024,Data!$C$2:$C$277,"contingent_consideration_noncurrent") | G20: =SUMIFS(Data!$D$2:$D$277,Data!$A$2:$A$277,"GSK",Data!$B$2:$B$277,2025,Data!$C$2:$C$277,"contingent_consideration_noncurrent") | H20: =SUMIFS(Data!$D$2:$D$277,Data!$A$2:$A$277,"Novo Nordisk",Data!$B$2:$B$277,2023,Data!$C$2:$C$277,"contingent_consideration_noncurrent") | I20: =SUMIFS(Data!$D$2:$D$277,Data!$A$2:$A$277,"Novo Nordisk",Data!$B$2:$B$277,2024,Data!$C$2:$C$277,"contingent_consideration_noncurrent") | J20: =SUMIFS(Data!$D$2:$D$277,Data!$A$2:$A$277,"Novo Nordisk",Data!$B$2:$B$277,2025,Data!$C$2:$C$277,"contingent_consideration_noncurrent")
A21: Cash and cash equivalents | B21: =SUMIFS(Data!$D$2:$D$277,Data!$A$2:$A$277,"Novartis",Data!$B$2:$B$277,2023,Data!$C$2:$C$277,"cash") | C21: =SUMIFS(Data!$D$2:$D$277,Data!$A$2:$A$277,"Novartis",Data!$B$2:$B$277,2024,Data!$C$2:$C$277,"cash") | D21: =SUMIFS(Data!$D$2:$D$277,Data!$A$2:$A$277,"Novartis",Data!$B$2:$B$277,2025,Data!$C$2:$C$277,"cash") | E21: =SUMIFS(Data!$D$2:$D$277,Data!$A$2:$A$277,"GSK",Data!$B$2:$B$277,2023,Data!$C$2:$C$277,"cash") | F21: =SUMIFS(Data!$D$2:$D$277,Data!$A$2:$A$277,"GSK",Data!$B$2:$B$277,2024,Data!$C$2:$C$277,"cash") | G21: =SUMIFS(Data!$D$2:$D$277,Data!$A$2:$A$277,"GSK",Data!$B$2:$B$277,2025,Data!$C$2:$C$277,"cash") | H21: =SUMIFS(Data!$D$2:$D$277,Data!$A$2:$A$277,"Novo Nordisk",Data!$B$2:$B$277,2023,Data!$C$2:$C$277,"cash") | I21: =SUMIFS(Data!$D$2:$D$277,Data!$A$2:$A$277,"Novo Nordisk",Data!$B$2:$B$277,2024,Data!$C$2:$C$277,"cash") | J21: =SUMIFS(Data!$D$2:$D$277,Data!$A$2:$A$277,"Novo Nordisk",Data!$B$2:$B$277,2025,Data!$C$2:$C$277,"cash")
A22: Marketable securities and short-term investments | B22: =SUMIFS(Data!$D$2:$D$277,Data!$A$2:$A$277,"Novartis",Data!$B$2:$B$277,2023,Data!$C$2:$C$277,"short_term_investments") | C22: =SUMIFS(Data!$D$2:$D$277,Data!$A$2:$A$277,"Novartis",Data!$B$2:$B$277,2024,Data!$C$2:$C$277,"short_term_investments") | D22: =SUMIFS(Data!$D$2:$D$277,Data!$A$2:$A$277,"Novartis",Data!$B$2:$B$277,2025,Data!$C$2:$C$277,"short_term_investments") | E22: =SUMIFS(Data!$D$2:$D$277,Data!$A$2:$A$277,"GSK",Data!$B$2:$B$277,2023,Data!$C$2:$C$277,"short_term_investments") | F22: =SUMIFS(Data!$D$2:$D$277,Data!$A$2:$A$277,"GSK",Data!$B$2:$B$277,2024,Data!$C$2:$C$277,"short_term_investments") | G22: =SUMIFS(Data!$D$2:$D$277,Data!$A$2:$A$277,"GSK",Data!$B$2:$B$277,2025,Data!$C$2:$C$277,"short_term_investments") | H22: =SUMIFS(Data!$D$2:$D$277,Data!$A$2:$A$277,"Novo Nordisk",Data!$B$2:$B$277,2023,Data!$C$2:$C$277,"short_term_investments") | I22: =SUMIFS(Data!$D$2:$D$277,Data!$A$2:$A$277,"Novo Nordisk",Data!$B$2:$B$277,2024,Data!$C$2:$C$277,"short_term_investments") | J22: =SUMIFS(Data!$D$2:$D$277,Data!$A$2:$A$277,"Novo Nordisk",Data!$B$2:$B$277,2025,Data!$C$2:$C$277,"short_term_investments")
A24: Revenue growth | B24: ="" | C24: =IF(ISNUMBER(B4),C4/B4-1,"") | D24: =IF(ISNUMBER(C4),D4/C4-1,"") | E24: ="" | F24: =IF(ISNUMBER(E4),F4/E4-1,"") | G24: =IF(ISNUMBER(F4),G4/F4-1,"") | H24: ="" | I24: =IF(ISNUMBER(H4),I4/H4-1,"") | J24: =IF(ISNUMBER(I4),J4/I4-1,"")
A25: Operating margin | B25: =B5/B4 | C25: =C5/C4 | D25: =D5/D4 | E25: =E5/E4 | F25: =F5/F4 | G25: =G5/G4 | H25: =H5/H4 | I25: =I5/I4 | J25: =J5/J4
A26: R&D as % of revenue | B26: =B6/B4 | C26: =C6/C4 | D26: =D6/D4 | E26: =E6/E4 | F26: =F6/F4 | G26: =G6/G4 | H26: =H6/H4 | I26: =I6/I4 | J26: =J6/J4
A27: Effective tax rate | B27: =B7/B8 | C27: =C7/C8 | D27: =D7/D8 | E27: =E7/E8 | F27: =F7/F8 | G27: =G7/G8 | H27: =H7/H8 | I27: =I7/I8 | J27: =J7/J8
A28: Net margin | B28: =B9/B4 | C28: =C9/C4 | D28: =D9/D4 | E28: =E9/E4 | F28: =F9/F4 | G28: =G9/G4 | H28: =H9/H4 | I28: =I9/I4 | J28: =J9/J4
A29: Free cash flow (after tax and net interest; before leases, acquisitions, dividends) | B29: =B10-B11-B12-B13+B14 | C29: =C10-C11-C12-C13+C14 | D29: =D10-D11-D12-D13+D14 | E29: =E10-E11-E12-E13+E14 | F29: =F10-F11-F12-F13+F14 | G29: =G10-G11-G12-G13+G14 | H29: =H10-H11-H12-H13+H14 | I29: =I10-I11-I12-I13+I14 | J29: =J10-J11-J12-J13+J14
A30: Free cash flow margin | B30: =B29/B4 | C30: =C29/C4 | D30: =D29/D4 | E30: =E29/E4 | F30: =F29/F4 | G30: =G29/G4 | H30: =H29/H4 | I30: =I29/I4 | J30: =J29/J4
A31: Free cash flow / net income | B31: =B29/B9 | C31: =C29/C9 | D31: =D29/D9 | E31: =E29/E9 | F31: =F29/F9 | G31: =G29/G9 | H31: =H29/H9 | I31: =I29/I9 | J31: =J29/J9
A32: Gross debt incl. leases | B32: =B15+B16+B17+B18 | C32: =C15+C16+C17+C18 | D32: =D15+D16+D17+D18 | E32: =E15+E16+E17+E18 | F32: =F15+F16+F17+F18 | G32: =G15+G16+G17+G18 | H32: =H15+H16+H17+H18 | I32: =I15+I16+I17+I18 | J32: =J15+J16+J17+J18
A33: Net debt incl. debt-like contingent consideration | B33: =B32+B19+B20-B21-B22 | C33: =C32+C19+C20-C21-C22 | D33: =D32+D19+D20-D21-D22 | E33: =E32+E19+E20-E21-E22 | F33: =F32+F19+F20-F21-F22 | G33: =G32+G19+G20-G21-G22 | H33: =H32+H19+H20-H21-H22 | I33: =I32+I19+I20-I21-I22 | J33: =J32+J19+J20-J21-J22
A34: Net debt / operating income | B34: =B33/B5 | C34: =C33/C5 | D34: =D33/D5 | E34: =E33/E5 | F34: =F33/F5 | G34: =G33/G5 | H34: =H33/H5 | I34: =I33/I5 | J34: =J33/J5

Sheet DCF
A1: Novartis DCF (USD millions unless stated)
A3: Base revenue (FY2025 net sales) | B3: =SUMIFS(Data!$D$2:$D$277,Data!$A$2:$A$277,"Novartis",Data!$B$2:$B$277,2025,Data!$C$2:$C$277,"revenue")
A4: Base net working capital (inventories + trade receivables - trade payables) | B4: =SUMIFS(Data!$D$2:$D$277,Data!$A$2:$A$277,"Novartis",Data!$B$2:$B$277,2025,Data!$C$2:$C$277,"inventories")+SUMIFS(Data!$D$2:$D$277,Data!$A$2:$A$277,"Novartis",Data!$B$2:$B$277,2025,Data!$C$2:$C$277,"receivables")-SUMIFS(Data!$D$2:$D$277,Data!$A$2:$A$277,"Novartis",Data!$B$2:$B$277,2025,Data!$C$2:$C$277,"payables")
A5: Tax rate (assumption) | B5: 0.16
A6: D&A as % of revenue (FY2025 depreciation + amortisation; excludes impairments) | B6: =(SUMIFS(Data!$D$2:$D$277,Data!$A$2:$A$277,"Novartis",Data!$B$2:$B$277,2025,Data!$C$2:$C$277,"depreciation_ppe")+SUMIFS(Data!$D$2:$D$277,Data!$A$2:$A$277,"Novartis",Data!$B$2:$B$277,2025,Data!$C$2:$C$277,"amortisation_intangibles"))/B3
A7: Capex as % of revenue (FY2025 PP&E + intangibles) | B7: =(SUMIFS(Data!$D$2:$D$277,Data!$A$2:$A$277,"Novartis",Data!$B$2:$B$277,2025,Data!$C$2:$C$277,"capex_ppe")+SUMIFS(Data!$D$2:$D$277,Data!$A$2:$A$277,"Novartis",Data!$B$2:$B$277,2025,Data!$C$2:$C$277,"capex_intangibles"))/B3
A8: Net working capital as % of revenue (held constant) | B8: =B4/B3
A9: Terminal growth (assumption) | B9: 0.02
A10: Risk-free rate (US 10-year, 2025-12-31) | B10: 0.0418
A11: Equity beta (assumption) | B11: 0.75
A12: Equity risk premium (Damodaran implied, 2026-01-01) | B12: 0.0423
A13: Pre-tax cost of debt (FY2025 interest expense / average gross debt) | B13: =SUMIFS(Data!$D$2:$D$277,Data!$A$2:$A$277,"Novartis",Data!$B$2:$B$277,2025,Data!$C$2:$C$277,"interest_expense")/((SUMIFS(Data!$D$2:$D$277,Data!$A$2:$A$277,"Novartis",Data!$B$2:$B$277,2025,Data!$C$2:$C$277,"debt_current")+SUMIFS(Data!$D$2:$D$277,Data!$A$2:$A$277,"Novartis",Data!$B$2:$B$277,2025,Data!$C$2:$C$277,"debt_noncurrent")+SUMIFS(Data!$D$2:$D$277,Data!$A$2:$A$277,"Novartis",Data!$B$2:$B$277,2025,Data!$C$2:$C$277,"lease_current")+SUMIFS(Data!$D$2:$D$277,Data!$A$2:$A$277,"Novartis",Data!$B$2:$B$277,2025,Data!$C$2:$C$277,"lease_noncurrent")+SUMIFS(Data!$D$2:$D$277,Data!$A$2:$A$277,"Novartis",Data!$B$2:$B$277,2024,Data!$C$2:$C$277,"debt_current")+SUMIFS(Data!$D$2:$D$277,Data!$A$2:$A$277,"Novartis",Data!$B$2:$B$277,2024,Data!$C$2:$C$277,"debt_noncurrent")+SUMIFS(Data!$D$2:$D$277,Data!$A$2:$A$277,"Novartis",Data!$B$2:$B$277,2024,Data!$C$2:$C$277,"lease_current")+SUMIFS(Data!$D$2:$D$277,Data!$A$2:$A$277,"Novartis",Data!$B$2:$B$277,2024,Data!$C$2:$C$277,"lease_noncurrent"))/2)
A14: Debt weight in capital structure (assumption; no market price available) | B14: 0.15
A15: Cost of equity | B15: =B10+B11*B12
A16: After-tax cost of debt | B16: =B13*(1-B5)
A17: WACC (overwrite with a number to test a different rate) | B17: =(1-B14)*B15+B14*B16
A18: Shares outstanding (millions, cover page) | B18: =SUMIFS(Data!$D$2:$D$277,Data!$A$2:$A$277,"Novartis",Data!$B$2:$B$277,2025,Data!$C$2:$C$277,"shares_outstanding_cover")
A19: Mid-year discounting (1 = yes, 0 = no) | B19: 0
A21: Projection
A22: Year | B22: 0 | C22: 1 | D22: 2 | E22: 3 | F22: 4 | G22: 5
A23: Revenue growth (assumption) | C23: 0.05 | D23: 0.045 | E23: 0.04 | F23: 0.035 | G23: 0.03
A24: Operating margin on net sales (assumption) | C24: 0.32 | D24: 0.315 | E24: 0.31 | F24: 0.305 | G24: 0.3
A25: Revenue | B25: =B3 | C25: =B25*(1+C23) | D25: =C25*(1+D23) | E25: =D25*(1+E23) | F25: =E25*(1+F23) | G25: =F25*(1+G23)
A26: Operating income (EBIT) | C26: =C25*C24 | D26: =D25*D24 | E26: =E25*E24 | F26: =F25*F24 | G26: =G25*G24
A27: NOPAT | C27: =C26*(1-$B$5) | D27: =D26*(1-$B$5) | E27: =E26*(1-$B$5) | F27: =F26*(1-$B$5) | G27: =G26*(1-$B$5)
A28: D&A | C28: =C25*$B$6 | D28: =D25*$B$6 | E28: =E25*$B$6 | F28: =F25*$B$6 | G28: =G25*$B$6
A29: Capex | C29: =C25*$B$7 | D29: =D25*$B$7 | E29: =E25*$B$7 | F29: =F25*$B$7 | G29: =G25*$B$7
A30: Net working capital | B30: =B4 | C30: =C25*$B$8 | D30: =D25*$B$8 | E30: =E25*$B$8 | F30: =F25*$B$8 | G30: =G25*$B$8
A31: Increase in net working capital | C31: =C30-B30 | D31: =D30-C30 | E31: =E30-D30 | F31: =F30-E30 | G31: =G30-F30
A32: Free cash flow to the firm | C32: =C27+C28-C29-C31 | D32: =D27+D28-D29-D31 | E32: =E27+E28-E29-E31 | F32: =F27+F28-F29-F31 | G32: =G27+G28-G29-G31
A33: Discount factor | C33: =1/(1+$B$17)^(C22-0.5*$B$19) | D33: =1/(1+$B$17)^(D22-0.5*$B$19) | E33: =1/(1+$B$17)^(E22-0.5*$B$19) | F33: =1/(1+$B$17)^(F22-0.5*$B$19) | G33: =1/(1+$B$17)^(G22-0.5*$B$19)
A34: Present value | C34: =C32*C33 | D34: =D32*D33 | E34: =E32*E33 | F34: =F32*F33 | G34: =G32*G33
A36: Terminal value and enterprise value
A37: First terminal-year free cash flow (D&A set equal to capex) | B37: =G27*(1+B9)-B8*G25*B9
A38: Terminal value at year 5 | B38: =B37/(B17-B9)
A39: Present value of terminal value | B39: =B38*G33
A40: Present value of explicit cash flows | B40: =SUM(C34:G34)
A41: Enterprise value | B41: =B40+B39
A42: Terminal value as % of enterprise value | B42: =B39/B41
A44: Enterprise value to equity value (FY2025 balance sheet)
...

Sheet Sensitivity
A1: Equity value per share (USD): WACC (rows) by terminal growth (columns)
A3: WACC \ g | B3: 0.01 | C3: 0.015 | D3: 0.02 | E3: 0.025 | F3: 0.03
A4: =DCF!$B$17+(-0.01) | B4: =(SUMPRODUCT(DCF!$C$32:$G$32,1/(1+$A4)^(DCF!$C$22:$G$22-0.5*DCF!$B$19))+(DCF!$G$27*(1+B$3)-DCF!$B$8*DCF!$G$25*B$3)/($A4-B$3)/(1+$A4)^(DCF!$G$22-0.5*DCF!$B$19)+DCF!$B$54)/DCF!$B$18 | C4: =(SUMPRODUCT(DCF!$C$32:$G$32,1/(1+$A4)^(DCF!$C$22:$G$22-0.5*DCF!$B$19))+(DCF!$G$27*(1+C$3)-DCF!$B$8*DCF!$G$25*C$3)/($A4-C$3)/(1+$A4)^(DCF!$G$22-0.5*DCF!$B$19)+DCF!$B$54)/DCF!$B$18 | D4: =(SUMPRODUCT(DCF!$C$32:$G$32,1/(1+$A4)^(DCF!$C$22:$G$22-0.5*DCF!$B$19))+(DCF!$G$27*(1+D$3)-DCF!$B$8*DCF!$G$25*D$3)/($A4-D$3)/(1+$A4)^(DCF!$G$22-0.5*DCF!$B$19)+DCF!$B$54)/DCF!$B$18 | E4: =(SUMPRODUCT(DCF!$C$32:$G$32,1/(1+$A4)^(DCF!$C$22:$G$22-0.5*DCF!$B$19))+(DCF!$G$27*(1+E$3)-DCF!$B$8*DCF!$G$25*E$3)/($A4-E$3)/(1+$A4)^(DCF!$G$22-0.5*DCF!$B$19)+DCF!$B$54)/DCF!$B$18 | F4: =(SUMPRODUCT(DCF!$C$32:$G$32,1/(1+$A4)^(DCF!$C$22:$G$22-0.5*DCF!$B$19))+(DCF!$G$27*(1+F$3)-DCF!$B$8*DCF!$G$25*F$3)/($A4-F$3)/(1+$A4)^(DCF!$G$22-0.5*DCF!$B$19)+DCF!$B$54)/DCF!$B$18
A5: =DCF!$B$17+(-0.005) | B5: =(SUMPRODUCT(DCF!$C$32:$G$32,1/(1+$A5)^(DCF!$C$22:$G$22-0.5*DCF!$B$19))+(DCF!$G$27*(1+B$3)-DCF!$B$8*DCF!$G$25*B$3)/($A5-B$3)/(1+$A5)^(DCF!$G$22-0.5*DCF!$B$19)+DCF!$B$54)/DCF!$B$18 | C5: =(SUMPRODUCT(DCF!$C$32:$G$32,1/(1+$A5)^(DCF!$C$22:$G$22-0.5*DCF!$B$19))+(DCF!$G$27*(1+C$3)-DCF!$B$8*DCF!$G$25*C$3)/($A5-C$3)/(1+$A5)^(DCF!$G$22-0.5*DCF!$B$19)+DCF!$B$54)/DCF!$B$18 | D5: =(SUMPRODUCT(DCF!$C$32:$G$32,1/(1+$A5)^(DCF!$C$22:$G$22-0.5*DCF!$B$19))+(DCF!$G$27*(1+D$3)-DCF!$B$8*DCF!$G$25*D$3)/($A5-D$3)/(1+$A5)^(DCF!$G$22-0.5*DCF!$B$19)+DCF!$B$54)/DCF!$B$18 | E5: =(SUMPRODUCT(DCF!$C$32:$G$32,1/(1+$A5)^(DCF!$C$22:$G$22-0.5*DCF!$B$19))+(DCF!$G$27*(1+E$3)-DCF!$B$8*DCF!$G$25*E$3)/($A5-E$3)/(1+$A5)^(DCF!$G$22-0.5*DCF!$B$19)+DCF!$B$54)/DCF!$B$18 | F5: =(SUMPRODUCT(DCF!$C$32:$G$32,1/(1+$A5)^(DCF!$C$22:$G$22-0.5*DCF!$B$19))+(DCF!$G$27*(1+F$3)-DCF!$B$8*DCF!$G$25*F$3)/($A5-F$3)/(1+$A5)^(DCF!$G$22-0.5*DCF!$B$19)+DCF!$B$54)/DCF!$B$18
A6: =DCF!$B$17+(0.0) | B6: =(SUMPRODUCT(DCF!$C$32:$G$32,1/(1+$A6)^(DCF!$C$22:$G$22-0.5*DCF!$B$19))+(DCF!$G$27*(1+B$3)-DCF!$B$8*DCF!$G$25*B$3)/($A6-B$3)/(1+$A6)^(DCF!$G$22-0.5*DCF!$B$19)+DCF!$B$54)/DCF!$B$18 | C6: =(SUMPRODUCT(DCF!$C$32:$G$32,1/(1+$A6)^(DCF!$C$22:$G$22-0.5*DCF!$B$19))+(DCF!$G$27*(1+C$3)-DCF!$B$8*DCF!$G$25*C$3)/($A6-C$3)/(1+$A6)^(DCF!$G$22-0.5*DCF!$B$19)+DCF!$B$54)/DCF!$B$18 | D6: =(SUMPRODUCT(DCF!$C$32:$G$32,1/(1+$A6)^(DCF!$C$22:$G$22-0.5*DCF!$B$19))+(DCF!$G$27*(1+D$3)-DCF!$B$8*DCF!$G$25*D$3)/($A6-D$3)/(1+$A6)^(DCF!$G$22-0.5*DCF!$B$19)+DCF!$B$54)/DCF!$B$18 | E6: =(SUMPRODUCT(DCF!$C$32:$G$32,1/(1+$A6)^(DCF!$C$22:$G$22-0.5*DCF!$B$19))+(DCF!$G$27*(1+E$3)-DCF!$B$8*DCF!$G$25*E$3)/($A6-E$3)/(1+$A6)^(DCF!$G$22-0.5*DCF!$B$19)+DCF!$B$54)/DCF!$B$18 | F6: =(SUMPRODUCT(DCF!$C$32:$G$32,1/(1+$A6)^(DCF!$C$22:$G$22-0.5*DCF!$B$19))+(DCF!$G$27*(1+F$3)-DCF!$B$8*DCF!$G$25*F$3)/($A6-F$3)/(1+$A6)^(DCF!$G$22-0.5*DCF!$B$19)+DCF!$B$54)/DCF!$B$18
A7: =DCF!$B$17+(0.005) | B7: =(SUMPRODUCT(DCF!$C$32:$G$32,1/(1+$A7)^(DCF!$C$22:$G$22-0.5*DCF!$B$19))+(DCF!$G$27*(1+B$3)-DCF!$B$8*DCF!$G$25*B$3)/($A7-B$3)/(1+$A7)^(DCF!$G$22-0.5*DCF!$B$19)+DCF!$B$54)/DCF!$B$18 | C7: =(SUMPRODUCT(DCF!$C$32:$G$32,1/(1+$A7)^(DCF!$C$22:$G$22-0.5*DCF!$B$19))+(DCF!$G$27*(1+C$3)-DCF!$B$8*DCF!$G$25*C$3)/($A7-C$3)/(1+$A7)^(DCF!$G$22-0.5*DCF!$B$19)+DCF!$B$54)/DCF!$B$18 | D7: =(SUMPRODUCT(DCF!$C$32:$G$32,1/(1+$A7)^(DCF!$C$22:$G$22-0.5*DCF!$B$19))+(DCF!$G$27*(1+D$3)-DCF!$B$8*DCF!$G$25*D$3)/($A7-D$3)/(1+$A7)^(DCF!$G$22-0.5*DCF!$B$19)+DCF!$B$54)/DCF!$B$18 | E7: =(SUMPRODUCT(DCF!$C$32:$G$32,1/(1+$A7)^(DCF!$C$22:$G$22-0.5*DCF!$B$19))+(DCF!$G$27*(1+E$3)-DCF!$B$8*DCF!$G$25*E$3)/($A7-E$3)/(1+$A7)^(DCF!$G$22-0.5*DCF!$B$19)+DCF!$B$54)/DCF!$B$18 | F7: =(SUMPRODUCT(DCF!$C$32:$G$32,1/(1+$A7)^(DCF!$C$22:$G$22-0.5*DCF!$B$19))+(DCF!$G$27*(1+F$3)-DCF!$B$8*DCF!$G$25*F$3)/($A7-F$3)/(1+$A7)^(DCF!$G$22-0.5*DCF!$B$19)+DCF!$B$54)/DCF!$B$18
A8: =DCF!$B$17+(0.01) | B8: =(SUMPRODUCT(DCF!$C$32:$G$32,1/(1+$A8)^(DCF!$C$22:$G$22-0.5*DCF!$B$19))+(DCF!$G$27*(1+B$3)-DCF!$B$8*DCF!$G$25*B$3)/($A8-B$3)/(1+$A8)^(DCF!$G$22-0.5*DCF!$B$19)+DCF!$B$54)/DCF!$B$18 | C8: =(SUMPRODUCT(DCF!$C$32:$G$32,1/(1+$A8)^(DCF!$C$22:$G$22-0.5*DCF!$B$19))+(DCF!$G$27*(1+C$3)-DCF!$B$8*DCF!$G$25*C$3)/($A8-C$3)/(1+$A8)^(DCF!$G$22-0.5*DCF!$B$19)+DCF!$B$54)/DCF!$B$18 | D8: =(SUMPRODUCT(DCF!$C$32:$G$32,1/(1+$A8)^(DCF!$C$22:$G$22-0.5*DCF!$B$19))+(DCF!$G$27*(1+D$3)-DCF!$B$8*DCF!$G$25*D$3)/($A8-D$3)/(1+$A8)^(DCF!$G$22-0.5*DCF!$B$19)+DCF!$B$54)/DCF!$B$18 | E8: =(SUMPRODUCT(DCF!$C$32:$G$32,1/(1+$A8)^(DCF!$C$22:$G$22-0.5*DCF!$B$19))+(DCF!$G$27*(1+E$3)-DCF!$B$8*DCF!$G$25*E$3)/($A8-E$3)/(1+$A8)^(DCF!$G$22-0.5*DCF!$B$19)+DCF!$B$54)/DCF!$B$18 | F8: =(SUMPRODUCT(DCF!$C$32:$G$32,1/(1+$A8)^(DCF!$C$22:$G$22-0.5*DCF!$B$19))+(DCF!$G$27*(1+F$3)-DCF!$B$8*DCF!$G$25*F$3)/($A8-F$3)/(1+$A8)^(DCF!$G$22-0.5*DCF!$B$19)+DCF!$B$54)/DCF!$B$18

Sheet Checks
A1: Checks (every value should read 0 or TRUE)
A3: Balance sheet identity Novartis 2023: assets - equity - liabilities | B3: =SUMIFS(Data!$D$2:$D$277,Data!$A$2:$A$277,"Novartis",Data!$B$2:$B$277,2023,Data!$C$2:$C$277,"total_assets")-SUMIFS(Data!$D$2:$D$277,Data!$A$2:$A$277,"Novartis",Data!$B$2:$B$277,2023,Data!$C$2:$C$277,"total_equity")-SUMIFS(Data!$D$2:$D$277,Data!$A$2:$A$277,"Novartis",Data!$B$2:$B$277,2023,Data!$C$2:$C$277,"total_liabilities")
A4: Balance sheet identity Novartis 2024: assets - equity - liabilities | B4: =SUMIFS(Data!$D$2:$D$277,Data!$A$2:$A$277,"Novartis",Data!$B$2:$B$277,2024,Data!$C$2:$C$277,"total_assets")-SUMIFS(Data!$D$2:$D$277,Data!$A$2:$A$277,"Novartis",Data!$B$2:$B$277,2024,Data!$C$2:$C$277,"total_equity")-SUMIFS(Data!$D$2:$D$277,Data!$A$2:$A$277,"Novartis",Data!$B$2:$B$277,2024,Data!$C$2:$C$277,"total_liabilities")
A5: Balance sheet identity Novartis 2025: assets - equity - liabilities | B5: =SUMIFS(Data!$D$2:$D$277,Data!$A$2:$A$277,"Novartis",Data!$B$2:$B$277,2025,Data!$C$2:$C$277,"total_assets")-SUMIFS(Data!$D$2:$D$277,Data!$A$2:$A$277,"Novartis",Data!$B$2:$B$277,2025,Data!$C$2:$C$277,"total_equity")-SUMIFS(Data!$D$2:$D$277,Data!$A$2:$A$277,"Novartis",Data!$B$2:$B$277,2025,Data!$C$2:$C$277,"total_liabilities")
A6: Balance sheet identity GSK 2023: assets - equity - liabilities | B6: =SUMIFS(Data!$D$2:$D$277,Data!$A$2:$A$277,"GSK",Data!$B$2:$B$277,2023,Data!$C$2:$C$277,"total_assets")-SUMIFS(Data!$D$2:$D$277,Data!$A$2:$A$277,"GSK",Data!$B$2:$B$277,2023,Data!$C$2:$C$277,"total_equity")-SUMIFS(Data!$D$2:$D$277,Data!$A$2:$A$277,"GSK",Data!$B$2:$B$277,2023,Data!$C$2:$C$277,"total_liabilities")
A7: Balance sheet identity GSK 2024: assets - equity - liabilities | B7: =SUMIFS(Data!$D$2:$D$277,Data!$A$2:$A$277,"GSK",Data!$B$2:$B$277,2024,Data!$C$2:$C$277,"total_assets")-SUMIFS(Data!$D$2:$D$277,Data!$A$2:$A$277,"GSK",Data!$B$2:$B$277,2024,Data!$C$2:$C$277,"total_equity")-SUMIFS(Data!$D$2:$D$277,Data!$A$2:$A$277,"GSK",Data!$B$2:$B$277,2024,Data!$C$2:$C$277,"total_liabilities")
A8: Balance sheet identity GSK 2025: assets - equity - liabilities | B8: =SUMIFS(Data!$D$2:$D$277,Data!$A$2:$A$277,"GSK",Data!$B$2:$B$277,2025,Data!$C$2:$C$277,"total_assets")-SUMIFS(Data!$D$2:$D$277,Data!$A$2:$A$277,"GSK",Data!$B$2:$B$277,2025,Data!$C$2:$C$277,"total_equity")-SUMIFS(Data!$D$2:$D$277,Data!$A$2:$A$277,"GSK",Data!$B$2:$B$277,2025,Data!$C$2:$C$277,"total_liabilities")
A9: Balance sheet identity Novo Nordisk 2023: assets - equity - liabilities | B9: =SUMIFS(Data!$D$2:$D$277,Data!$A$2:$A$277,"Novo Nordisk",Data!$B$2:$B$277,2023,Data!$C$2:$C$277,"total_assets")-SUMIFS(Data!$D$2:$D$277,Data!$A$2:$A$277,"Novo Nordisk",Data!$B$2:$B$277,2023,Data!$C$2:$C$277,"total_equity")-SUMIFS(Data!$D$2:$D$277,Data!$A$2:$A$277,"Novo Nordisk",Data!$B$2:$B$277,2023,Data!$C$2:$C$277,"total_liabilities")
A10: Balance sheet identity Novo Nordisk 2024: assets - equity - liabilities | B10: =SUMIFS(Data!$D$2:$D$277,Data!$A$2:$A$277,"Novo Nordisk",Data!$B$2:$B$277,2024,Data!$C$2:$C$277,"total_assets")-SUMIFS(Data!$D$2:$D$277,Data!$A$2:$A$277,"Novo Nordisk",Data!$B$2:$B$277,2024,Data!$C$2:$C$277,"total_equity")-SUMIFS(Data!$D$2:$D$277,Data!$A$2:$A$277,"Novo Nordisk",Data!$B$2:$B$277,2024,Data!$C$2:$C$277,"total_liabilities")
A11: Balance sheet identity Novo Nordisk 2025: assets - equity - liabilities | B11: =SUMIFS(Data!$D$2:$D$277,Data!$A$2:$A$277,"Novo Nordisk",Data!$B$2:$B$277,2025,Data!$C$2:$C$277,"total_assets")-SUMIFS(Data!$D$2:$D$277,Data!$A$2:$A$277,"Novo Nordisk",Data!$B$2:$B$277,2025,Data!$C$2:$C$277,"total_equity")-SUMIFS(Data!$D$2:$D$277,Data!$A$2:$A$277,"Novo Nordisk",Data!$B$2:$B$277,2025,Data!$C$2:$C$277,"total_liabilities")
A12: WACC exceeds terminal growth | B12: =DCF!B17>DCF!B9
A13: Bridge sums to equity value | B13: =ABS(SUM(DCF!B45:B52)-DCF!B53)<0.001
